[2024-07-22T09:12:17.430+0000] {local_task_job_runner.py:120} INFO - ::group::Pre task execution logs
[2024-07-22T09:12:17.439+0000] {taskinstance.py:2076} INFO - Dependencies all met for dep_context=non-requeueable deps ti=<TaskInstance: dag_with_postgres_hooks.plot manual__2024-07-22T09:11:58.479420+00:00 [queued]>
[2024-07-22T09:12:17.442+0000] {taskinstance.py:2076} INFO - Dependencies all met for dep_context=requeueable deps ti=<TaskInstance: dag_with_postgres_hooks.plot manual__2024-07-22T09:11:58.479420+00:00 [queued]>
[2024-07-22T09:12:17.442+0000] {taskinstance.py:2306} INFO - Starting attempt 1 of 1
[2024-07-22T09:12:17.446+0000] {taskinstance.py:2330} INFO - Executing <Task(PythonOperator): plot> on 2024-07-22 09:11:58.479420+00:00
[2024-07-22T09:12:17.451+0000] {warnings.py:112} WARNING - /home/***/.local/lib/python3.12/site-packages/***/task/task_runner/standard_task_runner.py:62: DeprecationWarning: This process (pid=5700) is multi-threaded, use of fork() may lead to deadlocks in the child.
  pid = os.fork()

[2024-07-22T09:12:17.451+0000] {standard_task_runner.py:64} INFO - Started process 5711 to run task
[2024-07-22T09:12:17.452+0000] {standard_task_runner.py:90} INFO - Running: ['***', 'tasks', 'run', 'dag_with_postgres_hooks', 'plot', 'manual__2024-07-22T09:11:58.479420+00:00', '--job-id', '544', '--raw', '--subdir', 'DAGS_FOLDER/Stock_pred.py', '--cfg-path', '/tmp/tmplh6zx34h']
[2024-07-22T09:12:17.453+0000] {standard_task_runner.py:91} INFO - Job 544: Subtask plot
[2024-07-22T09:12:17.469+0000] {task_command.py:426} INFO - Running <TaskInstance: dag_with_postgres_hooks.plot manual__2024-07-22T09:11:58.479420+00:00 [running]> on host d89911194c67
[2024-07-22T09:12:17.497+0000] {taskinstance.py:2648} INFO - Exporting env vars: AIRFLOW_CTX_DAG_EMAIL='***@example.com' AIRFLOW_CTX_DAG_OWNER='***' AIRFLOW_CTX_DAG_ID='dag_with_postgres_hooks' AIRFLOW_CTX_TASK_ID='plot' AIRFLOW_CTX_EXECUTION_DATE='2024-07-22T09:11:58.479420+00:00' AIRFLOW_CTX_TRY_NUMBER='1' AIRFLOW_CTX_DAG_RUN_ID='manual__2024-07-22T09:11:58.479420+00:00'
[2024-07-22T09:12:17.498+0000] {taskinstance.py:430} INFO - ::endgroup::
[2024-07-22T09:12:17.518+0000] {logging_mixin.py:188} INFO -            DATE    CLOSE  CLOSE_diff1
0    2020-07-17   8570.0          NaN
1    2020-07-20   8466.0       -104.0
2    2020-07-21   8501.0         35.0
3    2020-07-22   8432.0        -69.0
4    2020-07-23   8363.0        -69.0
..          ...      ...          ...
445  2024-07-16  24100.0        150.0
446  2024-07-17  24500.0        400.0
447  2024-07-18  24800.0        300.0
448  2024-07-19  25100.0        300.0
449  2024-07-22  24750.0       -350.0

[450 rows x 3 columns]
[2024-07-22T09:12:17.526+0000] {warnings.py:112} WARNING - /opt/***/dags/Stock_pred.py:308: UserWarning: Parsing dates in %d/%m/%Y format when dayfirst=False (the default) was specified. Pass `dayfirst=True` or specify a format to silence this warning.
  date_after = pd.to_datetime(date) + timedelta(days=1)

[2024-07-22T09:12:17.528+0000] {warnings.py:112} WARNING - /opt/***/dags/Stock_pred.py:310: UserWarning: Parsing dates in %d/%m/%Y format when dayfirst=False (the default) was specified. Pass `dayfirst=True` or specify a format to silence this warning.
  df_ts_pred.index = pd.to_datetime(df_ts_pred.index).date

[2024-07-22T09:12:17.530+0000] {logging_mixin.py:188} INFO -        CLOSE        DATE
0     8570.0  2020-07-17
1     8466.0  2020-07-20
2     8501.0  2020-07-21
3     8432.0  2020-07-22
4     8363.0  2020-07-23
..       ...         ...
445  24100.0  2024-07-16
446  24500.0  2024-07-17
447  24800.0  2024-07-18
448  25100.0  2024-07-19
449  24750.0  2024-07-22

[450 rows x 2 columns]
[2024-07-22T09:12:17.531+0000] {logging_mixin.py:188} INFO -      pred_index        date
0  24750.000000  2024-07-22
1  24772.589844  2024-07-23
[2024-07-22T09:12:17.539+0000] {taskinstance.py:441} INFO - ::group::Post task execution logs
[2024-07-22T09:12:17.539+0000] {taskinstance.py:2905} ERROR - Task failed with exception
Traceback (most recent call last):
  File "/home/airflow/.local/lib/python3.12/site-packages/pandas/core/indexes/base.py", line 3791, in get_loc
    return self._engine.get_loc(casted_key)
           ^^^^^^^^^^^^^^^^^^^^^^^^^^^^^^^^
  File "index.pyx", line 152, in pandas._libs.index.IndexEngine.get_loc
  File "index.pyx", line 181, in pandas._libs.index.IndexEngine.get_loc
  File "pandas/_libs/hashtable_class_helper.pxi", line 7080, in pandas._libs.hashtable.PyObjectHashTable.get_item
  File "pandas/_libs/hashtable_class_helper.pxi", line 7088, in pandas._libs.hashtable.PyObjectHashTable.get_item
KeyError: 'date'

The above exception was the direct cause of the following exception:

Traceback (most recent call last):
  File "/home/airflow/.local/lib/python3.12/site-packages/airflow/models/taskinstance.py", line 465, in _execute_task
    result = _execute_callable(context=context, **execute_callable_kwargs)
             ^^^^^^^^^^^^^^^^^^^^^^^^^^^^^^^^^^^^^^^^^^^^^^^^^^^^^^^^^^^^^
  File "/home/airflow/.local/lib/python3.12/site-packages/airflow/models/taskinstance.py", line 432, in _execute_callable
    return execute_callable(context=context, **execute_callable_kwargs)
           ^^^^^^^^^^^^^^^^^^^^^^^^^^^^^^^^^^^^^^^^^^^^^^^^^^^^^^^^^^^^
  File "/home/airflow/.local/lib/python3.12/site-packages/airflow/models/baseoperator.py", line 401, in wrapper
    return func(self, *args, **kwargs)
           ^^^^^^^^^^^^^^^^^^^^^^^^^^^
  File "/home/airflow/.local/lib/python3.12/site-packages/airflow/operators/python.py", line 235, in execute
    return_value = self.execute_callable()
                   ^^^^^^^^^^^^^^^^^^^^^^^
  File "/home/airflow/.local/lib/python3.12/site-packages/airflow/operators/python.py", line 252, in execute_callable
    return self.python_callable(*self.op_args, **self.op_kwargs)
           ^^^^^^^^^^^^^^^^^^^^^^^^^^^^^^^^^^^^^^^^^^^^^^^^^^^^^
  File "/opt/airflow/dags/Stock_pred.py", line 320, in plot
    ax.plot(b['date'].iloc[-10:],b['CLOSE'].iloc[-10:],color="gray")
            ~^^^^^^^^
  File "/home/airflow/.local/lib/python3.12/site-packages/pandas/core/frame.py", line 3893, in __getitem__
    indexer = self.columns.get_loc(key)
              ^^^^^^^^^^^^^^^^^^^^^^^^^
  File "/home/airflow/.local/lib/python3.12/site-packages/pandas/core/indexes/base.py", line 3798, in get_loc
    raise KeyError(key) from err
KeyError: 'date'
[2024-07-22T09:12:17.545+0000] {taskinstance.py:1206} INFO - Marking task as FAILED. dag_id=dag_with_postgres_hooks, task_id=plot, run_id=manual__2024-07-22T09:11:58.479420+00:00, execution_date=20240722T091158, start_date=20240722T091217, end_date=20240722T091217
[2024-07-22T09:12:17.550+0000] {standard_task_runner.py:110} ERROR - Failed to execute job 544 for task plot ('date'; 5711)
[2024-07-22T09:12:17.592+0000] {local_task_job_runner.py:243} INFO - Task exited with return code 1
[2024-07-22T09:12:17.602+0000] {taskinstance.py:3503} INFO - 0 downstream tasks scheduled from follow-on schedule check
[2024-07-22T09:12:17.604+0000] {local_task_job_runner.py:222} INFO - ::endgroup::
