[2025-03-05T23:52:55.931+0000] {local_task_job_runner.py:120} INFO - ::group::Pre task execution logs
[2025-03-05T23:52:55.980+0000] {taskinstance.py:2076} INFO - Dependencies all met for dep_context=non-requeueable deps ti=<TaskInstance: dag_with_postgres_hooks.scrap_new_data scheduled__2025-02-25T13:30:00+00:00 [queued]>
[2025-03-05T23:52:55.988+0000] {taskinstance.py:2076} INFO - Dependencies all met for dep_context=requeueable deps ti=<TaskInstance: dag_with_postgres_hooks.scrap_new_data scheduled__2025-02-25T13:30:00+00:00 [queued]>
[2025-03-05T23:52:55.989+0000] {taskinstance.py:2306} INFO - Starting attempt 1 of 1
[2025-03-05T23:52:55.998+0000] {taskinstance.py:2330} INFO - Executing <Task(PythonOperator): scrap_new_data> on 2025-02-25 13:30:00+00:00
[2025-03-05T23:52:56.009+0000] {warnings.py:112} WARNING - /home/***/.local/lib/python3.12/site-packages/***/task/task_runner/standard_task_runner.py:62: DeprecationWarning: This process (pid=214) is multi-threaded, use of fork() may lead to deadlocks in the child.
  pid = os.fork()

[2025-03-05T23:52:56.012+0000] {standard_task_runner.py:64} INFO - Started process 244 to run task
[2025-03-05T23:52:56.016+0000] {standard_task_runner.py:90} INFO - Running: ['***', 'tasks', 'run', 'dag_with_postgres_hooks', 'scrap_new_data', 'scheduled__2025-02-25T13:30:00+00:00', '--job-id', '1565', '--raw', '--subdir', 'DAGS_FOLDER/Stock_pred.py', '--cfg-path', '/tmp/tmp343ics6k']
[2025-03-05T23:52:56.017+0000] {standard_task_runner.py:91} INFO - Job 1565: Subtask scrap_new_data
[2025-03-05T23:52:56.077+0000] {task_command.py:426} INFO - Running <TaskInstance: dag_with_postgres_hooks.scrap_new_data scheduled__2025-02-25T13:30:00+00:00 [running]> on host b7aba691e1ff
[2025-03-05T23:52:56.147+0000] {taskinstance.py:2648} INFO - Exporting env vars: AIRFLOW_CTX_DAG_EMAIL='***@example.com' AIRFLOW_CTX_DAG_OWNER='***' AIRFLOW_CTX_DAG_ID='dag_with_postgres_hooks' AIRFLOW_CTX_TASK_ID='scrap_new_data' AIRFLOW_CTX_EXECUTION_DATE='2025-02-25T13:30:00+00:00' AIRFLOW_CTX_TRY_NUMBER='1' AIRFLOW_CTX_DAG_RUN_ID='scheduled__2025-02-25T13:30:00+00:00'
[2025-03-05T23:52:56.148+0000] {taskinstance.py:430} INFO - ::endgroup::
[2025-03-05T23:53:05.178+0000] {taskinstance.py:441} INFO - ::group::Post task execution logs
[2025-03-05T23:53:05.911+0000] {taskinstance.py:2905} ERROR - Task failed with exception
Traceback (most recent call last):
  File "/home/airflow/.local/lib/python3.12/site-packages/urllib3/connection.py", line 203, in _new_conn
    sock = connection.create_connection(
           ^^^^^^^^^^^^^^^^^^^^^^^^^^^^^
  File "/home/airflow/.local/lib/python3.12/site-packages/urllib3/util/connection.py", line 60, in create_connection
    for res in socket.getaddrinfo(host, port, family, socket.SOCK_STREAM):
               ^^^^^^^^^^^^^^^^^^^^^^^^^^^^^^^^^^^^^^^^^^^^^^^^^^^^^^^^^^
  File "/usr/local/lib/python3.12/socket.py", line 964, in getaddrinfo
    for res in _socket.getaddrinfo(host, port, family, type, proto, flags):
               ^^^^^^^^^^^^^^^^^^^^^^^^^^^^^^^^^^^^^^^^^^^^^^^^^^^^^^^^^^^
socket.gaierror: [Errno -3] Temporary failure in name resolution

The above exception was the direct cause of the following exception:

Traceback (most recent call last):
  File "/home/airflow/.local/lib/python3.12/site-packages/urllib3/connectionpool.py", line 791, in urlopen
    response = self._make_request(
               ^^^^^^^^^^^^^^^^^^^
  File "/home/airflow/.local/lib/python3.12/site-packages/urllib3/connectionpool.py", line 497, in _make_request
    conn.request(
  File "/home/airflow/.local/lib/python3.12/site-packages/urllib3/connection.py", line 395, in request
    self.endheaders()
  File "/usr/local/lib/python3.12/http/client.py", line 1331, in endheaders
    self._send_output(message_body, encode_chunked=encode_chunked)
  File "/usr/local/lib/python3.12/http/client.py", line 1091, in _send_output
    self.send(msg)
  File "/usr/local/lib/python3.12/http/client.py", line 1035, in send
    self.connect()
  File "/home/airflow/.local/lib/python3.12/site-packages/urllib3/connection.py", line 243, in connect
    self.sock = self._new_conn()
                ^^^^^^^^^^^^^^^^
  File "/home/airflow/.local/lib/python3.12/site-packages/urllib3/connection.py", line 210, in _new_conn
    raise NameResolutionError(self.host, self, e) from e
urllib3.exceptions.NameResolutionError: <urllib3.connection.HTTPConnection object at 0xffff2e10fd40>: Failed to resolve 'en.stockbiz.vn' ([Errno -3] Temporary failure in name resolution)

The above exception was the direct cause of the following exception:

Traceback (most recent call last):
  File "/home/airflow/.local/lib/python3.12/site-packages/requests/adapters.py", line 667, in send
    resp = conn.urlopen(
           ^^^^^^^^^^^^^
  File "/home/airflow/.local/lib/python3.12/site-packages/urllib3/connectionpool.py", line 845, in urlopen
    retries = retries.increment(
              ^^^^^^^^^^^^^^^^^^
  File "/home/airflow/.local/lib/python3.12/site-packages/urllib3/util/retry.py", line 515, in increment
    raise MaxRetryError(_pool, url, reason) from reason  # type: ignore[arg-type]
    ^^^^^^^^^^^^^^^^^^^^^^^^^^^^^^^^^^^^^^^^^^^^^^^^^^^
urllib3.exceptions.MaxRetryError: HTTPConnectionPool(host='en.stockbiz.vn', port=80): Max retries exceeded with url: /Stocks/ACB/LookupQuote.aspx?Date=2025-03-05 (Caused by NameResolutionError("<urllib3.connection.HTTPConnection object at 0xffff2e10fd40>: Failed to resolve 'en.stockbiz.vn' ([Errno -3] Temporary failure in name resolution)"))

During handling of the above exception, another exception occurred:

Traceback (most recent call last):
  File "/home/airflow/.local/lib/python3.12/site-packages/airflow/models/taskinstance.py", line 465, in _execute_task
    result = _execute_callable(context=context, **execute_callable_kwargs)
             ^^^^^^^^^^^^^^^^^^^^^^^^^^^^^^^^^^^^^^^^^^^^^^^^^^^^^^^^^^^^^
  File "/home/airflow/.local/lib/python3.12/site-packages/airflow/models/taskinstance.py", line 432, in _execute_callable
    return execute_callable(context=context, **execute_callable_kwargs)
           ^^^^^^^^^^^^^^^^^^^^^^^^^^^^^^^^^^^^^^^^^^^^^^^^^^^^^^^^^^^^
  File "/home/airflow/.local/lib/python3.12/site-packages/airflow/models/baseoperator.py", line 401, in wrapper
    return func(self, *args, **kwargs)
           ^^^^^^^^^^^^^^^^^^^^^^^^^^^
  File "/home/airflow/.local/lib/python3.12/site-packages/airflow/operators/python.py", line 235, in execute
    return_value = self.execute_callable()
                   ^^^^^^^^^^^^^^^^^^^^^^^
  File "/home/airflow/.local/lib/python3.12/site-packages/airflow/operators/python.py", line 252, in execute_callable
    return self.python_callable(*self.op_args, **self.op_kwargs)
           ^^^^^^^^^^^^^^^^^^^^^^^^^^^^^^^^^^^^^^^^^^^^^^^^^^^^^
  File "/opt/airflow/dags/Stock_pred.py", line 64, in scrap_stock
    html = requests.get(f'http://en.stockbiz.vn/Stocks/ACB/LookupQuote.aspx?Date={date}').text
           ^^^^^^^^^^^^^^^^^^^^^^^^^^^^^^^^^^^^^^^^^^^^^^^^^^^^^^^^^^^^^^^^^^^^^^^^^^^^^^
  File "/home/airflow/.local/lib/python3.12/site-packages/requests/api.py", line 73, in get
    return request("get", url, params=params, **kwargs)
           ^^^^^^^^^^^^^^^^^^^^^^^^^^^^^^^^^^^^^^^^^^^^
  File "/home/airflow/.local/lib/python3.12/site-packages/requests/api.py", line 59, in request
    return session.request(method=method, url=url, **kwargs)
           ^^^^^^^^^^^^^^^^^^^^^^^^^^^^^^^^^^^^^^^^^^^^^^^^^
  File "/home/airflow/.local/lib/python3.12/site-packages/requests/sessions.py", line 589, in request
    resp = self.send(prep, **send_kwargs)
           ^^^^^^^^^^^^^^^^^^^^^^^^^^^^^^
  File "/home/airflow/.local/lib/python3.12/site-packages/requests/sessions.py", line 703, in send
    r = adapter.send(request, **kwargs)
        ^^^^^^^^^^^^^^^^^^^^^^^^^^^^^^^
  File "/home/airflow/.local/lib/python3.12/site-packages/requests/adapters.py", line 700, in send
    raise ConnectionError(e, request=request)
requests.exceptions.ConnectionError: HTTPConnectionPool(host='en.stockbiz.vn', port=80): Max retries exceeded with url: /Stocks/ACB/LookupQuote.aspx?Date=2025-03-05 (Caused by NameResolutionError("<urllib3.connection.HTTPConnection object at 0xffff2e10fd40>: Failed to resolve 'en.stockbiz.vn' ([Errno -3] Temporary failure in name resolution)"))
[2025-03-05T23:53:27.835+0000] {taskinstance.py:1206} INFO - Marking task as FAILED. dag_id=dag_with_postgres_hooks, task_id=scrap_new_data, run_id=scheduled__2025-02-25T13:30:00+00:00, execution_date=20250225T133000, start_date=20250305T235255, end_date=20250305T235327
[2025-03-05T23:53:28.318+0000] {standard_task_runner.py:110} ERROR - Failed to execute job 1565 for task scrap_new_data (HTTPConnectionPool(host='en.stockbiz.vn', port=80): Max retries exceeded with url: /Stocks/ACB/LookupQuote.aspx?Date=2025-03-05 (Caused by NameResolutionError("<urllib3.connection.HTTPConnection object at 0xffff2e10fd40>: Failed to resolve 'en.stockbiz.vn' ([Errno -3] Temporary failure in name resolution)")); 244)
[2025-03-05T23:53:28.408+0000] {local_task_job_runner.py:243} INFO - Task exited with return code 1
[2025-03-05T23:53:28.513+0000] {taskinstance.py:3503} INFO - 0 downstream tasks scheduled from follow-on schedule check
[2025-03-05T23:53:28.536+0000] {local_task_job_runner.py:222} INFO - ::endgroup::
