[2024-07-17T09:32:42.049+0000] {local_task_job_runner.py:120} INFO - ::group::Pre task execution logs
[2024-07-17T09:32:42.057+0000] {taskinstance.py:2076} INFO - Dependencies all met for dep_context=non-requeueable deps ti=<TaskInstance: dag_with_postgres_hooks.featur_engineer manual__2024-07-17T09:32:37.093386+00:00 [queued]>
[2024-07-17T09:32:42.060+0000] {taskinstance.py:2076} INFO - Dependencies all met for dep_context=requeueable deps ti=<TaskInstance: dag_with_postgres_hooks.featur_engineer manual__2024-07-17T09:32:37.093386+00:00 [queued]>
[2024-07-17T09:32:42.060+0000] {taskinstance.py:2306} INFO - Starting attempt 1 of 1
[2024-07-17T09:32:42.132+0000] {taskinstance.py:2330} INFO - Executing <Task(PythonOperator): featur_engineer> on 2024-07-17 09:32:37.093386+00:00
[2024-07-17T09:32:42.135+0000] {warnings.py:112} WARNING - /home/***/.local/lib/python3.12/site-packages/***/task/task_runner/standard_task_runner.py:61: DeprecationWarning: This process (pid=429) is multi-threaded, use of fork() may lead to deadlocks in the child.
  pid = os.fork()

[2024-07-17T09:32:42.136+0000] {standard_task_runner.py:63} INFO - Started process 438 to run task
[2024-07-17T09:32:42.136+0000] {standard_task_runner.py:90} INFO - Running: ['***', 'tasks', 'run', 'dag_with_postgres_hooks', 'featur_engineer', 'manual__2024-07-17T09:32:37.093386+00:00', '--job-id', '71', '--raw', '--subdir', 'DAGS_FOLDER/sql_2.py', '--cfg-path', '/tmp/tmpr9_p8n4_']
[2024-07-17T09:32:42.137+0000] {standard_task_runner.py:91} INFO - Job 71: Subtask featur_engineer
[2024-07-17T09:32:42.154+0000] {task_command.py:426} INFO - Running <TaskInstance: dag_with_postgres_hooks.featur_engineer manual__2024-07-17T09:32:37.093386+00:00 [running]> on host 0c2114842aea
[2024-07-17T09:32:42.180+0000] {taskinstance.py:2648} INFO - Exporting env vars: AIRFLOW_CTX_DAG_EMAIL='***@example.com' AIRFLOW_CTX_DAG_OWNER='***' AIRFLOW_CTX_DAG_ID='dag_with_postgres_hooks' AIRFLOW_CTX_TASK_ID='featur_engineer' AIRFLOW_CTX_EXECUTION_DATE='2024-07-17T09:32:37.093386+00:00' AIRFLOW_CTX_TRY_NUMBER='1' AIRFLOW_CTX_DAG_RUN_ID='manual__2024-07-17T09:32:37.093386+00:00'
[2024-07-17T09:32:42.180+0000] {taskinstance.py:430} INFO - ::endgroup::
[2024-07-17T09:32:42.734+0000] {warnings.py:112} WARNING - /opt/***/dags/sql_2.py:228: SettingWithCopyWarning: 
A value is trying to be set on a copy of a slice from a DataFrame

See the caveats in the documentation: https://pandas.pydata.org/pandas-docs/stable/user_guide/indexing.html#returning-a-view-versus-a-copy
  input.drop(columns=["Target","CLOSE_t+1"],inplace=True)

[2024-07-17T09:32:42.743+0000] {connectionpool.py:874} WARNING - Retrying (Retry(total=4, connect=None, read=None, redirect=None, status=None)) after connection broken by 'NewConnectionError('<urllib3.connection.HTTPSConnection object at 0xffff9c1bfb00>: Failed to establish a new connection: [Errno 111] Connection refused')': /mlflow-artifacts?location=
[2024-07-17T09:32:43.147+0000] {connectionpool.py:874} WARNING - Retrying (Retry(total=3, connect=None, read=None, redirect=None, status=None)) after connection broken by 'NewConnectionError('<urllib3.connection.HTTPSConnection object at 0xffff9c219040>: Failed to establish a new connection: [Errno 111] Connection refused')': /mlflow-artifacts?location=
[2024-07-17T09:32:43.955+0000] {connectionpool.py:874} WARNING - Retrying (Retry(total=2, connect=None, read=None, redirect=None, status=None)) after connection broken by 'NewConnectionError('<urllib3.connection.HTTPSConnection object at 0xffff9c2191c0>: Failed to establish a new connection: [Errno 111] Connection refused')': /mlflow-artifacts?location=
[2024-07-17T09:32:45.563+0000] {connectionpool.py:874} WARNING - Retrying (Retry(total=1, connect=None, read=None, redirect=None, status=None)) after connection broken by 'NewConnectionError('<urllib3.connection.HTTPSConnection object at 0xffff9c219550>: Failed to establish a new connection: [Errno 111] Connection refused')': /mlflow-artifacts?location=
[2024-07-17T09:32:48.768+0000] {connectionpool.py:874} WARNING - Retrying (Retry(total=0, connect=None, read=None, redirect=None, status=None)) after connection broken by 'NewConnectionError('<urllib3.connection.HTTPSConnection object at 0xffff9c2197f0>: Failed to establish a new connection: [Errno 111] Connection refused')': /mlflow-artifacts?location=
[2024-07-17T09:32:48.769+0000] {taskinstance.py:441} INFO - ::group::Post task execution logs
[2024-07-17T09:32:48.770+0000] {taskinstance.py:2905} ERROR - Task failed with exception
Traceback (most recent call last):
  File "/home/airflow/.local/lib/python3.12/site-packages/urllib3/connection.py", line 198, in _new_conn
    sock = connection.create_connection(
           ^^^^^^^^^^^^^^^^^^^^^^^^^^^^^
  File "/home/airflow/.local/lib/python3.12/site-packages/urllib3/util/connection.py", line 85, in create_connection
    raise err
  File "/home/airflow/.local/lib/python3.12/site-packages/urllib3/util/connection.py", line 73, in create_connection
    sock.connect(sa)
ConnectionRefusedError: [Errno 111] Connection refused

The above exception was the direct cause of the following exception:

Traceback (most recent call last):
  File "/home/airflow/.local/lib/python3.12/site-packages/urllib3/connectionpool.py", line 793, in urlopen
    response = self._make_request(
               ^^^^^^^^^^^^^^^^^^^
  File "/home/airflow/.local/lib/python3.12/site-packages/urllib3/connectionpool.py", line 491, in _make_request
    raise new_e
  File "/home/airflow/.local/lib/python3.12/site-packages/urllib3/connectionpool.py", line 467, in _make_request
    self._validate_conn(conn)
  File "/home/airflow/.local/lib/python3.12/site-packages/urllib3/connectionpool.py", line 1099, in _validate_conn
    conn.connect()
  File "/home/airflow/.local/lib/python3.12/site-packages/urllib3/connection.py", line 616, in connect
    self.sock = sock = self._new_conn()
                       ^^^^^^^^^^^^^^^^
  File "/home/airflow/.local/lib/python3.12/site-packages/urllib3/connection.py", line 213, in _new_conn
    raise NewConnectionError(
urllib3.exceptions.NewConnectionError: <urllib3.connection.HTTPSConnection object at 0xffff9c219a30>: Failed to establish a new connection: [Errno 111] Connection refused

The above exception was the direct cause of the following exception:

Traceback (most recent call last):
  File "/home/airflow/.local/lib/python3.12/site-packages/airflow/models/taskinstance.py", line 465, in _execute_task
    result = _execute_callable(context=context, **execute_callable_kwargs)
             ^^^^^^^^^^^^^^^^^^^^^^^^^^^^^^^^^^^^^^^^^^^^^^^^^^^^^^^^^^^^^
  File "/home/airflow/.local/lib/python3.12/site-packages/airflow/models/taskinstance.py", line 432, in _execute_callable
    return execute_callable(context=context, **execute_callable_kwargs)
           ^^^^^^^^^^^^^^^^^^^^^^^^^^^^^^^^^^^^^^^^^^^^^^^^^^^^^^^^^^^^
  File "/home/airflow/.local/lib/python3.12/site-packages/airflow/models/baseoperator.py", line 401, in wrapper
    return func(self, *args, **kwargs)
           ^^^^^^^^^^^^^^^^^^^^^^^^^^^
  File "/home/airflow/.local/lib/python3.12/site-packages/airflow/operators/python.py", line 235, in execute
    return_value = self.execute_callable()
                   ^^^^^^^^^^^^^^^^^^^^^^^
  File "/home/airflow/.local/lib/python3.12/site-packages/airflow/operators/python.py", line 252, in execute_callable
    return self.python_callable(*self.op_args, **self.op_kwargs)
           ^^^^^^^^^^^^^^^^^^^^^^^^^^^^^^^^^^^^^^^^^^^^^^^^^^^^^
  File "/opt/airflow/dags/sql_2.py", line 230, in transform_data
    response = client.get_object("mlflow-artifacts", "model.pkl")
               ^^^^^^^^^^^^^^^^^^^^^^^^^^^^^^^^^^^^^^^^^^^^^^^^^^
  File "/home/airflow/.local/lib/python3.12/site-packages/minio/api.py", line 1244, in get_object
    return self._execute(
           ^^^^^^^^^^^^^^
  File "/home/airflow/.local/lib/python3.12/site-packages/minio/api.py", line 437, in _execute
    region = self._get_region(bucket_name)
             ^^^^^^^^^^^^^^^^^^^^^^^^^^^^^
  File "/home/airflow/.local/lib/python3.12/site-packages/minio/api.py", line 494, in _get_region
    response = self._url_open(
               ^^^^^^^^^^^^^^^
  File "/home/airflow/.local/lib/python3.12/site-packages/minio/api.py", line 302, in _url_open
    response = self._http.urlopen(
               ^^^^^^^^^^^^^^^^^^^
  File "/home/airflow/.local/lib/python3.12/site-packages/urllib3/poolmanager.py", line 444, in urlopen
    response = conn.urlopen(method, u.request_uri, **kw)
               ^^^^^^^^^^^^^^^^^^^^^^^^^^^^^^^^^^^^^^^^^
  File "/home/airflow/.local/lib/python3.12/site-packages/urllib3/connectionpool.py", line 877, in urlopen
    return self.urlopen(
           ^^^^^^^^^^^^^
  File "/home/airflow/.local/lib/python3.12/site-packages/urllib3/connectionpool.py", line 877, in urlopen
    return self.urlopen(
           ^^^^^^^^^^^^^
  File "/home/airflow/.local/lib/python3.12/site-packages/urllib3/connectionpool.py", line 877, in urlopen
    return self.urlopen(
           ^^^^^^^^^^^^^
  [Previous line repeated 2 more times]
  File "/home/airflow/.local/lib/python3.12/site-packages/urllib3/connectionpool.py", line 847, in urlopen
    retries = retries.increment(
              ^^^^^^^^^^^^^^^^^^
  File "/home/airflow/.local/lib/python3.12/site-packages/urllib3/util/retry.py", line 515, in increment
    raise MaxRetryError(_pool, url, reason) from reason  # type: ignore[arg-type]
    ^^^^^^^^^^^^^^^^^^^^^^^^^^^^^^^^^^^^^^^^^^^^^^^^^^^
urllib3.exceptions.MaxRetryError: HTTPSConnectionPool(host='127.0.0.1', port=9000): Max retries exceeded with url: /mlflow-artifacts?location= (Caused by NewConnectionError('<urllib3.connection.HTTPSConnection object at 0xffff9c219a30>: Failed to establish a new connection: [Errno 111] Connection refused'))
[2024-07-17T09:32:48.778+0000] {taskinstance.py:1206} INFO - Marking task as FAILED. dag_id=dag_with_postgres_hooks, task_id=featur_engineer, run_id=manual__2024-07-17T09:32:37.093386+00:00, execution_date=20240717T093237, start_date=20240717T093242, end_date=20240717T093248
[2024-07-17T09:32:48.784+0000] {standard_task_runner.py:110} ERROR - Failed to execute job 71 for task featur_engineer (HTTPSConnectionPool(host='127.0.0.1', port=9000): Max retries exceeded with url: /mlflow-artifacts?location= (Caused by NewConnectionError('<urllib3.connection.HTTPSConnection object at 0xffff9c219a30>: Failed to establish a new connection: [Errno 111] Connection refused')); 438)
[2024-07-17T09:32:48.805+0000] {local_task_job_runner.py:240} INFO - Task exited with return code 1
[2024-07-17T09:32:48.815+0000] {taskinstance.py:3503} INFO - 0 downstream tasks scheduled from follow-on schedule check
[2024-07-17T09:32:48.817+0000] {local_task_job_runner.py:222} INFO - ::endgroup::
