[2024-07-03T15:42:12.818+0000] {local_task_job_runner.py:120} INFO - ::group::Pre task execution logs
[2024-07-03T15:42:12.828+0000] {taskinstance.py:2076} INFO - Dependencies all met for dep_context=non-requeueable deps ti=<TaskInstance: dag_with_postgres_operator_v03.create_postgres_table manual__2024-07-03T15:42:10.409711+00:00 [queued]>
[2024-07-03T15:42:12.830+0000] {taskinstance.py:2076} INFO - Dependencies all met for dep_context=requeueable deps ti=<TaskInstance: dag_with_postgres_operator_v03.create_postgres_table manual__2024-07-03T15:42:10.409711+00:00 [queued]>
[2024-07-03T15:42:12.831+0000] {taskinstance.py:2306} INFO - Starting attempt 1 of 1
[2024-07-03T15:42:12.840+0000] {taskinstance.py:2330} INFO - Executing <Task(PostgresOperator): create_postgres_table> on 2024-07-03 15:42:10.409711+00:00
[2024-07-03T15:42:12.844+0000] {warnings.py:112} WARNING - /home/***/.local/lib/python3.12/site-packages/***/task/task_runner/standard_task_runner.py:61: DeprecationWarning: This process (pid=55) is multi-threaded, use of fork() may lead to deadlocks in the child.
  pid = os.fork()

[2024-07-03T15:42:12.845+0000] {standard_task_runner.py:90} INFO - Running: ['***', 'tasks', 'run', 'dag_with_postgres_operator_v03', 'create_postgres_table', 'manual__2024-07-03T15:42:10.409711+00:00', '--job-id', '269', '--raw', '--subdir', 'DAGS_FOLDER/sql.py', '--cfg-path', '/tmp/tmpppzzgwqf']
[2024-07-03T15:42:12.847+0000] {standard_task_runner.py:63} INFO - Started process 57 to run task
[2024-07-03T15:42:12.847+0000] {standard_task_runner.py:91} INFO - Job 269: Subtask create_postgres_table
[2024-07-03T15:42:12.870+0000] {task_command.py:426} INFO - Running <TaskInstance: dag_with_postgres_operator_v03.create_postgres_table manual__2024-07-03T15:42:10.409711+00:00 [running]> on host 73a0e5a00b20
[2024-07-03T15:42:12.917+0000] {taskinstance.py:2648} INFO - Exporting env vars: AIRFLOW_CTX_DAG_EMAIL='***@example.com' AIRFLOW_CTX_DAG_OWNER='***' AIRFLOW_CTX_DAG_ID='dag_with_postgres_operator_v03' AIRFLOW_CTX_TASK_ID='create_postgres_table' AIRFLOW_CTX_EXECUTION_DATE='2024-07-03T15:42:10.409711+00:00' AIRFLOW_CTX_TRY_NUMBER='1' AIRFLOW_CTX_DAG_RUN_ID='manual__2024-07-03T15:42:10.409711+00:00'
[2024-07-03T15:42:12.918+0000] {taskinstance.py:430} INFO - ::endgroup::
[2024-07-03T15:42:12.918+0000] {sql.py:276} INFO - Executing: 
            create table if not exists dag_runs (
                dt date,
                dag_id character varying,
                primary key (dt, dag_id)
            )
        
[2024-07-03T15:42:12.921+0000] {base.py:84} INFO - Using connection ID 'Postgres' for task execution.
[2024-07-03T15:42:12.926+0000] {base.py:84} INFO - Using connection ID 'Postgres' for task execution.
[2024-07-03T15:42:12.930+0000] {taskinstance.py:441} INFO - ::group::Post task execution logs
[2024-07-03T15:42:12.930+0000] {taskinstance.py:2905} ERROR - Task failed with exception
Traceback (most recent call last):
  File "/home/airflow/.local/lib/python3.12/site-packages/airflow/models/taskinstance.py", line 465, in _execute_task
    result = _execute_callable(context=context, **execute_callable_kwargs)
             ^^^^^^^^^^^^^^^^^^^^^^^^^^^^^^^^^^^^^^^^^^^^^^^^^^^^^^^^^^^^^
  File "/home/airflow/.local/lib/python3.12/site-packages/airflow/models/taskinstance.py", line 432, in _execute_callable
    return execute_callable(context=context, **execute_callable_kwargs)
           ^^^^^^^^^^^^^^^^^^^^^^^^^^^^^^^^^^^^^^^^^^^^^^^^^^^^^^^^^^^^
  File "/home/airflow/.local/lib/python3.12/site-packages/airflow/models/baseoperator.py", line 401, in wrapper
    return func(self, *args, **kwargs)
           ^^^^^^^^^^^^^^^^^^^^^^^^^^^
  File "/home/airflow/.local/lib/python3.12/site-packages/airflow/providers/common/sql/operators/sql.py", line 282, in execute
    output = hook.run(
             ^^^^^^^^^
  File "/home/airflow/.local/lib/python3.12/site-packages/airflow/providers/common/sql/hooks/sql.py", line 431, in run
    with self._create_autocommit_connection(autocommit) as conn:
  File "/usr/local/lib/python3.12/contextlib.py", line 137, in __enter__
    return next(self.gen)
           ^^^^^^^^^^^^^^
  File "/home/airflow/.local/lib/python3.12/site-packages/airflow/providers/common/sql/hooks/sql.py", line 551, in _create_autocommit_connection
    with closing(self.get_conn()) as conn:
                 ^^^^^^^^^^^^^^^
  File "/home/airflow/.local/lib/python3.12/site-packages/airflow/providers/postgres/hooks/postgres.py", line 175, in get_conn
    self.conn = psycopg2.connect(**conn_args)
                ^^^^^^^^^^^^^^^^^^^^^^^^^^^^^
  File "/home/airflow/.local/lib/python3.12/site-packages/psycopg2/__init__.py", line 122, in connect
    conn = _connect(dsn, connection_factory=connection_factory, **kwasync)
           ^^^^^^^^^^^^^^^^^^^^^^^^^^^^^^^^^^^^^^^^^^^^^^^^^^^^^^^^^^^^^^^
psycopg2.OperationalError: connection to server at "host.docker.internal" (192.168.65.254), port 5432 failed: FATAL:  could not open file "global/pg_filenode.map": Operation not permitted

[2024-07-03T15:42:12.934+0000] {taskinstance.py:1206} INFO - Marking task as FAILED. dag_id=dag_with_postgres_operator_v03, task_id=create_postgres_table, run_id=manual__2024-07-03T15:42:10.409711+00:00, execution_date=20240703T154210, start_date=20240703T154212, end_date=20240703T154212
[2024-07-03T15:42:12.938+0000] {standard_task_runner.py:110} ERROR - Failed to execute job 269 for task create_postgres_table (connection to server at "host.docker.internal" (192.168.65.254), port 5432 failed: FATAL:  could not open file "global/pg_filenode.map": Operation not permitted
; 57)
[2024-07-03T15:42:12.946+0000] {local_task_job_runner.py:240} INFO - Task exited with return code 1
[2024-07-03T15:42:12.951+0000] {warnings.py:112} WARNING - /home/***/.local/lib/python3.12/site-packages/***/models/baseoperator.py:1297: AirflowProviderDeprecationWarning: Call to deprecated class PostgresOperator. (Please use `***.providers.common.sql.operators.sql.SQLExecuteQueryOperator`.Also, you can provide `hook_params={'schema': <database>}`.)
  result = cls.__new__(cls)

[2024-07-03T15:42:12.956+0000] {taskinstance.py:3503} INFO - 0 downstream tasks scheduled from follow-on schedule check
[2024-07-03T15:42:12.958+0000] {local_task_job_runner.py:222} INFO - ::endgroup::
