[2024-07-16T10:21:36.488+0000] {local_task_job_runner.py:120} INFO - ::group::Pre task execution logs
[2024-07-16T10:21:36.501+0000] {taskinstance.py:2076} INFO - Dependencies all met for dep_context=non-requeueable deps ti=<TaskInstance: mlflow_tutorial_dag.create_experiment manual__2024-07-16T10:21:34.228256+00:00 [queued]>
[2024-07-16T10:21:36.504+0000] {taskinstance.py:2076} INFO - Dependencies all met for dep_context=requeueable deps ti=<TaskInstance: mlflow_tutorial_dag.create_experiment manual__2024-07-16T10:21:34.228256+00:00 [queued]>
[2024-07-16T10:21:36.504+0000] {taskinstance.py:2306} INFO - Starting attempt 1 of 1
[2024-07-16T10:21:36.509+0000] {taskinstance.py:2330} INFO - Executing <Task(_PythonDecoratedOperator): create_experiment> on 2024-07-16 10:21:34.228256+00:00
[2024-07-16T10:21:36.513+0000] {warnings.py:112} WARNING - /home/***/.local/lib/python3.12/site-packages/***/task/task_runner/standard_task_runner.py:61: DeprecationWarning: This process (pid=2539) is multi-threaded, use of fork() may lead to deadlocks in the child.
  pid = os.fork()

[2024-07-16T10:21:36.514+0000] {standard_task_runner.py:63} INFO - Started process 2541 to run task
[2024-07-16T10:21:36.514+0000] {standard_task_runner.py:90} INFO - Running: ['***', 'tasks', 'run', 'mlflow_tutorial_dag', 'create_experiment', 'manual__2024-07-16T10:21:34.228256+00:00', '--job-id', '5', '--raw', '--subdir', 'DAGS_FOLDER/mlflow_tutorial_dag.py', '--cfg-path', '/tmp/tmp8chq6jp9']
[2024-07-16T10:21:36.515+0000] {standard_task_runner.py:91} INFO - Job 5: Subtask create_experiment
[2024-07-16T10:21:36.533+0000] {task_command.py:426} INFO - Running <TaskInstance: mlflow_tutorial_dag.create_experiment manual__2024-07-16T10:21:34.228256+00:00 [running]> on host 0afb0df8c7ed
[2024-07-16T10:21:36.563+0000] {taskinstance.py:2648} INFO - Exporting env vars: AIRFLOW_CTX_DAG_OWNER='***' AIRFLOW_CTX_DAG_ID='mlflow_tutorial_dag' AIRFLOW_CTX_TASK_ID='create_experiment' AIRFLOW_CTX_EXECUTION_DATE='2024-07-16T10:21:34.228256+00:00' AIRFLOW_CTX_TRY_NUMBER='1' AIRFLOW_CTX_DAG_RUN_ID='manual__2024-07-16T10:21:34.228256+00:00'
[2024-07-16T10:21:36.563+0000] {taskinstance.py:430} INFO - ::endgroup::
[2024-07-16T10:21:36.567+0000] {base.py:84} INFO - Using connection ID 'mlflow_default' for task execution.
[2024-07-16T10:21:36.568+0000] {client.py:119} INFO - Sending 'POST' to url: http://0.0.0.0:5005/api/2.0/mlflow/experiments/create
[2024-07-16T10:21:36.570+0000] {taskinstance.py:441} INFO - ::group::Post task execution logs
[2024-07-16T10:21:36.570+0000] {taskinstance.py:2905} ERROR - Task failed with exception
Traceback (most recent call last):
  File "/home/airflow/.local/lib/python3.12/site-packages/urllib3/connection.py", line 198, in _new_conn
    sock = connection.create_connection(
           ^^^^^^^^^^^^^^^^^^^^^^^^^^^^^
  File "/home/airflow/.local/lib/python3.12/site-packages/urllib3/util/connection.py", line 85, in create_connection
    raise err
  File "/home/airflow/.local/lib/python3.12/site-packages/urllib3/util/connection.py", line 73, in create_connection
    sock.connect(sa)
ConnectionRefusedError: [Errno 111] Connection refused

The above exception was the direct cause of the following exception:

Traceback (most recent call last):
  File "/home/airflow/.local/lib/python3.12/site-packages/urllib3/connectionpool.py", line 793, in urlopen
    response = self._make_request(
               ^^^^^^^^^^^^^^^^^^^
  File "/home/airflow/.local/lib/python3.12/site-packages/urllib3/connectionpool.py", line 496, in _make_request
    conn.request(
  File "/home/airflow/.local/lib/python3.12/site-packages/urllib3/connection.py", line 400, in request
    self.endheaders()
  File "/usr/local/lib/python3.12/http/client.py", line 1331, in endheaders
    self._send_output(message_body, encode_chunked=encode_chunked)
  File "/usr/local/lib/python3.12/http/client.py", line 1091, in _send_output
    self.send(msg)
  File "/usr/local/lib/python3.12/http/client.py", line 1035, in send
    self.connect()
  File "/home/airflow/.local/lib/python3.12/site-packages/urllib3/connection.py", line 238, in connect
    self.sock = self._new_conn()
                ^^^^^^^^^^^^^^^^
  File "/home/airflow/.local/lib/python3.12/site-packages/urllib3/connection.py", line 213, in _new_conn
    raise NewConnectionError(
urllib3.exceptions.NewConnectionError: <urllib3.connection.HTTPConnection object at 0xffff8df13e90>: Failed to establish a new connection: [Errno 111] Connection refused

The above exception was the direct cause of the following exception:

Traceback (most recent call last):
  File "/home/airflow/.local/lib/python3.12/site-packages/requests/adapters.py", line 486, in send
    resp = conn.urlopen(
           ^^^^^^^^^^^^^
  File "/home/airflow/.local/lib/python3.12/site-packages/urllib3/connectionpool.py", line 847, in urlopen
    retries = retries.increment(
              ^^^^^^^^^^^^^^^^^^
  File "/home/airflow/.local/lib/python3.12/site-packages/urllib3/util/retry.py", line 515, in increment
    raise MaxRetryError(_pool, url, reason) from reason  # type: ignore[arg-type]
    ^^^^^^^^^^^^^^^^^^^^^^^^^^^^^^^^^^^^^^^^^^^^^^^^^^^
urllib3.exceptions.MaxRetryError: HTTPConnectionPool(host='0.0.0.0', port=5005): Max retries exceeded with url: /api/2.0/mlflow/experiments/create (Caused by NewConnectionError('<urllib3.connection.HTTPConnection object at 0xffff8df13e90>: Failed to establish a new connection: [Errno 111] Connection refused'))

During handling of the above exception, another exception occurred:

Traceback (most recent call last):
  File "/home/airflow/.local/lib/python3.12/site-packages/airflow/models/taskinstance.py", line 465, in _execute_task
    result = _execute_callable(context=context, **execute_callable_kwargs)
             ^^^^^^^^^^^^^^^^^^^^^^^^^^^^^^^^^^^^^^^^^^^^^^^^^^^^^^^^^^^^^
  File "/home/airflow/.local/lib/python3.12/site-packages/airflow/models/taskinstance.py", line 432, in _execute_callable
    return execute_callable(context=context, **execute_callable_kwargs)
           ^^^^^^^^^^^^^^^^^^^^^^^^^^^^^^^^^^^^^^^^^^^^^^^^^^^^^^^^^^^^
  File "/home/airflow/.local/lib/python3.12/site-packages/airflow/models/baseoperator.py", line 401, in wrapper
    return func(self, *args, **kwargs)
           ^^^^^^^^^^^^^^^^^^^^^^^^^^^
  File "/home/airflow/.local/lib/python3.12/site-packages/airflow/decorators/base.py", line 265, in execute
    return_value = super().execute(context)
                   ^^^^^^^^^^^^^^^^^^^^^^^^
  File "/home/airflow/.local/lib/python3.12/site-packages/airflow/models/baseoperator.py", line 401, in wrapper
    return func(self, *args, **kwargs)
           ^^^^^^^^^^^^^^^^^^^^^^^^^^^
  File "/home/airflow/.local/lib/python3.12/site-packages/airflow/operators/python.py", line 235, in execute
    return_value = self.execute_callable()
                   ^^^^^^^^^^^^^^^^^^^^^^^
  File "/home/airflow/.local/lib/python3.12/site-packages/airflow/operators/python.py", line 252, in execute_callable
    return self.python_callable(*self.op_args, **self.op_kwargs)
           ^^^^^^^^^^^^^^^^^^^^^^^^^^^^^^^^^^^^^^^^^^^^^^^^^^^^^
  File "/opt/airflow/dags/mlflow_tutorial_dag.py", line 40, in create_experiment
    new_experiment_information = mlflow_hook.run(
                                 ^^^^^^^^^^^^^^^^
  File "/home/airflow/.local/lib/python3.12/site-packages/mlflow_provider/hooks/client.py", line 126, in run
    raise ex
  File "/home/airflow/.local/lib/python3.12/site-packages/mlflow_provider/hooks/client.py", line 122, in run
    response = session.send(prepped_request)
               ^^^^^^^^^^^^^^^^^^^^^^^^^^^^^
  File "/home/airflow/.local/lib/python3.12/site-packages/requests/sessions.py", line 703, in send
    r = adapter.send(request, **kwargs)
        ^^^^^^^^^^^^^^^^^^^^^^^^^^^^^^^
  File "/home/airflow/.local/lib/python3.12/site-packages/requests/adapters.py", line 519, in send
    raise ConnectionError(e, request=request)
requests.exceptions.ConnectionError: HTTPConnectionPool(host='0.0.0.0', port=5005): Max retries exceeded with url: /api/2.0/mlflow/experiments/create (Caused by NewConnectionError('<urllib3.connection.HTTPConnection object at 0xffff8df13e90>: Failed to establish a new connection: [Errno 111] Connection refused'))
[2024-07-16T10:21:36.579+0000] {taskinstance.py:1206} INFO - Marking task as FAILED. dag_id=mlflow_tutorial_dag, task_id=create_experiment, run_id=manual__2024-07-16T10:21:34.228256+00:00, execution_date=20240716T102134, start_date=20240716T102136, end_date=20240716T102136
[2024-07-16T10:21:36.584+0000] {standard_task_runner.py:110} ERROR - Failed to execute job 5 for task create_experiment (HTTPConnectionPool(host='0.0.0.0', port=5005): Max retries exceeded with url: /api/2.0/mlflow/experiments/create (Caused by NewConnectionError('<urllib3.connection.HTTPConnection object at 0xffff8df13e90>: Failed to establish a new connection: [Errno 111] Connection refused')); 2541)
[2024-07-16T10:21:36.617+0000] {local_task_job_runner.py:240} INFO - Task exited with return code 1
[2024-07-16T10:21:36.630+0000] {taskinstance.py:3503} INFO - 0 downstream tasks scheduled from follow-on schedule check
[2024-07-16T10:21:36.632+0000] {local_task_job_runner.py:222} INFO - ::endgroup::
