[2025-02-02T16:23:48.691+0000] {local_task_job_runner.py:120} INFO - ::group::Pre task execution logs
[2025-02-02T16:23:48.699+0000] {taskinstance.py:2076} INFO - Dependencies all met for dep_context=non-requeueable deps ti=<TaskInstance: dag_with_postgres_hooks.pred_time_series manual__2025-02-02T16:23:29.864526+00:00 [queued]>
[2025-02-02T16:23:48.702+0000] {taskinstance.py:2076} INFO - Dependencies all met for dep_context=requeueable deps ti=<TaskInstance: dag_with_postgres_hooks.pred_time_series manual__2025-02-02T16:23:29.864526+00:00 [queued]>
[2025-02-02T16:23:48.702+0000] {taskinstance.py:2306} INFO - Starting attempt 1 of 1
[2025-02-02T16:23:48.706+0000] {taskinstance.py:2330} INFO - Executing <Task(PythonOperator): pred_time_series> on 2025-02-02 16:23:29.864526+00:00
[2025-02-02T16:23:48.711+0000] {warnings.py:112} WARNING - /home/***/.local/lib/python3.12/site-packages/***/task/task_runner/standard_task_runner.py:62: DeprecationWarning: This process (pid=1077) is multi-threaded, use of fork() may lead to deadlocks in the child.
  pid = os.fork()

[2025-02-02T16:23:48.712+0000] {standard_task_runner.py:64} INFO - Started process 1084 to run task
[2025-02-02T16:23:48.712+0000] {standard_task_runner.py:90} INFO - Running: ['***', 'tasks', 'run', 'dag_with_postgres_hooks', 'pred_time_series', 'manual__2025-02-02T16:23:29.864526+00:00', '--job-id', '1512', '--raw', '--subdir', 'DAGS_FOLDER/Stock_pred.py', '--cfg-path', '/tmp/tmpfilmo6kp']
[2025-02-02T16:23:48.713+0000] {standard_task_runner.py:91} INFO - Job 1512: Subtask pred_time_series
[2025-02-02T16:23:48.728+0000] {task_command.py:426} INFO - Running <TaskInstance: dag_with_postgres_hooks.pred_time_series manual__2025-02-02T16:23:29.864526+00:00 [running]> on host b7aba691e1ff
[2025-02-02T16:23:48.757+0000] {taskinstance.py:2648} INFO - Exporting env vars: AIRFLOW_CTX_DAG_EMAIL='***@example.com' AIRFLOW_CTX_DAG_OWNER='***' AIRFLOW_CTX_DAG_ID='dag_with_postgres_hooks' AIRFLOW_CTX_TASK_ID='pred_time_series' AIRFLOW_CTX_EXECUTION_DATE='2025-02-02T16:23:29.864526+00:00' AIRFLOW_CTX_TRY_NUMBER='1' AIRFLOW_CTX_DAG_RUN_ID='manual__2025-02-02T16:23:29.864526+00:00'
[2025-02-02T16:23:48.758+0000] {taskinstance.py:430} INFO - ::endgroup::
[2025-02-02T16:23:48.832+0000] {warnings.py:112} WARNING - /opt/***/dags/Stock_pred.py:275: SettingWithCopyWarning: 
A value is trying to be set on a copy of a slice from a DataFrame

See the caveats in the documentation: https://pandas.pydata.org/pandas-docs/stable/user_guide/indexing.html#returning-a-view-versus-a-copy
  df_new_ts.rename(index={0:date},inplace=True)

[2025-02-02T16:23:48.833+0000] {logging_mixin.py:188} INFO - Index([  2022-12-30,   2023-01-03,   2023-01-04,   2023-01-05,   2023-01-06,
         2023-01-09,   2023-01-10,   2023-01-19,   2023-01-27,   2023-01-31,
       ...
         2025-01-10,   2025-01-13,   2025-01-14,   2025-01-15,   2025-01-20,
         2025-01-21,   2025-01-22,   2025-01-23,   2025-02-02, '2025-02-02'],
      dtype='object', length=189)
[2025-02-02T16:23:48.841+0000] {base.py:84} INFO - Using connection ID 'postgres_server_2' for task execution.
[2025-02-02T16:23:48.879+0000] {taskinstance.py:441} INFO - ::group::Post task execution logs
[2025-02-02T16:23:48.879+0000] {taskinstance.py:2905} ERROR - Task failed with exception
Traceback (most recent call last):
  File "/home/airflow/.local/lib/python3.12/site-packages/airflow/models/taskinstance.py", line 465, in _execute_task
    result = _execute_callable(context=context, **execute_callable_kwargs)
             ^^^^^^^^^^^^^^^^^^^^^^^^^^^^^^^^^^^^^^^^^^^^^^^^^^^^^^^^^^^^^
  File "/home/airflow/.local/lib/python3.12/site-packages/airflow/models/taskinstance.py", line 432, in _execute_callable
    return execute_callable(context=context, **execute_callable_kwargs)
           ^^^^^^^^^^^^^^^^^^^^^^^^^^^^^^^^^^^^^^^^^^^^^^^^^^^^^^^^^^^^
  File "/home/airflow/.local/lib/python3.12/site-packages/airflow/models/baseoperator.py", line 401, in wrapper
    return func(self, *args, **kwargs)
           ^^^^^^^^^^^^^^^^^^^^^^^^^^^
  File "/home/airflow/.local/lib/python3.12/site-packages/airflow/operators/python.py", line 235, in execute
    return_value = self.execute_callable()
                   ^^^^^^^^^^^^^^^^^^^^^^^
  File "/home/airflow/.local/lib/python3.12/site-packages/airflow/operators/python.py", line 252, in execute_callable
    return self.python_callable(*self.op_args, **self.op_kwargs)
           ^^^^^^^^^^^^^^^^^^^^^^^^^^^^^^^^^^^^^^^^^^^^^^^^^^^^^
  File "/opt/airflow/dags/Stock_pred.py", line 298, in pred_time_series
    pred_ts = model.predict(input)
              ^^^^^^^^^^^^^^^^^^^^
  File "/home/airflow/.local/lib/python3.12/site-packages/xgboost/sklearn.py", line 1186, in predict
    predts = self.get_booster().inplace_predict(
             ^^^^^^^^^^^^^^^^^^^^^^^^^^^^^^^^^^^
  File "/home/airflow/.local/lib/python3.12/site-packages/xgboost/core.py", line 2520, in inplace_predict
    raise ValueError(
ValueError: Feature shape mismatch, expected: 26, got 25
[2025-02-02T16:23:48.885+0000] {taskinstance.py:1206} INFO - Marking task as FAILED. dag_id=dag_with_postgres_hooks, task_id=pred_time_series, run_id=manual__2025-02-02T16:23:29.864526+00:00, execution_date=20250202T162329, start_date=20250202T162348, end_date=20250202T162348
[2025-02-02T16:23:48.892+0000] {standard_task_runner.py:110} ERROR - Failed to execute job 1512 for task pred_time_series (Feature shape mismatch, expected: 26, got 25; 1084)
[2025-02-02T16:23:48.933+0000] {local_task_job_runner.py:243} INFO - Task exited with return code 1
[2025-02-02T16:23:48.942+0000] {taskinstance.py:3503} INFO - 0 downstream tasks scheduled from follow-on schedule check
[2025-02-02T16:23:48.945+0000] {local_task_job_runner.py:222} INFO - ::endgroup::
