[2024-07-16T14:14:11.292+0000] {local_task_job_runner.py:120} INFO - ::group::Pre task execution logs
[2024-07-16T14:14:11.300+0000] {taskinstance.py:2076} INFO - Dependencies all met for dep_context=non-requeueable deps ti=<TaskInstance: dag_with_postgres_hooks.predict_mlflow manual__2024-07-16T14:14:03.434794+00:00 [queued]>
[2024-07-16T14:14:11.303+0000] {taskinstance.py:2076} INFO - Dependencies all met for dep_context=requeueable deps ti=<TaskInstance: dag_with_postgres_hooks.predict_mlflow manual__2024-07-16T14:14:03.434794+00:00 [queued]>
[2024-07-16T14:14:11.303+0000] {taskinstance.py:2306} INFO - Starting attempt 1 of 1
[2024-07-16T14:14:11.308+0000] {taskinstance.py:2330} INFO - Executing <Task(ModelLoadAndPredictOperator): predict_mlflow> on 2024-07-16 14:14:03.434794+00:00
[2024-07-16T14:14:11.311+0000] {warnings.py:112} WARNING - /home/***/.local/lib/python3.12/site-packages/***/task/task_runner/standard_task_runner.py:61: DeprecationWarning: This process (pid=623) is multi-threaded, use of fork() may lead to deadlocks in the child.
  pid = os.fork()

[2024-07-16T14:14:11.312+0000] {standard_task_runner.py:63} INFO - Started process 632 to run task
[2024-07-16T14:14:11.312+0000] {standard_task_runner.py:90} INFO - Running: ['***', 'tasks', 'run', 'dag_with_postgres_hooks', 'predict_mlflow', 'manual__2024-07-16T14:14:03.434794+00:00', '--job-id', '30', '--raw', '--subdir', 'DAGS_FOLDER/sql_2.py', '--cfg-path', '/tmp/tmpfl6i16dh']
[2024-07-16T14:14:11.313+0000] {standard_task_runner.py:91} INFO - Job 30: Subtask predict_mlflow
[2024-07-16T14:14:11.328+0000] {task_command.py:426} INFO - Running <TaskInstance: dag_with_postgres_hooks.predict_mlflow manual__2024-07-16T14:14:03.434794+00:00 [running]> on host 8d28ae2d2ca1
[2024-07-16T14:14:11.372+0000] {taskinstance.py:2648} INFO - Exporting env vars: AIRFLOW_CTX_DAG_EMAIL='***@example.com' AIRFLOW_CTX_DAG_OWNER='***' AIRFLOW_CTX_DAG_ID='dag_with_postgres_hooks' AIRFLOW_CTX_TASK_ID='predict_mlflow' AIRFLOW_CTX_EXECUTION_DATE='2024-07-16T14:14:03.434794+00:00' AIRFLOW_CTX_TRY_NUMBER='1' AIRFLOW_CTX_DAG_RUN_ID='manual__2024-07-16T14:14:03.434794+00:00'
[2024-07-16T14:14:11.373+0000] {taskinstance.py:430} INFO - ::endgroup::
[2024-07-16T14:14:11.376+0000] {base.py:84} INFO - Using connection ID 'mlflow_default' for task execution.
[2024-07-16T14:14:11.477+0000] {taskinstance.py:441} INFO - ::group::Post task execution logs
[2024-07-16T14:14:11.478+0000] {taskinstance.py:2905} ERROR - Task failed with exception
Traceback (most recent call last):
  File "/home/airflow/.local/lib/python3.12/site-packages/airflow/models/taskinstance.py", line 465, in _execute_task
    result = _execute_callable(context=context, **execute_callable_kwargs)
             ^^^^^^^^^^^^^^^^^^^^^^^^^^^^^^^^^^^^^^^^^^^^^^^^^^^^^^^^^^^^^
  File "/home/airflow/.local/lib/python3.12/site-packages/airflow/models/taskinstance.py", line 432, in _execute_callable
    return execute_callable(context=context, **execute_callable_kwargs)
           ^^^^^^^^^^^^^^^^^^^^^^^^^^^^^^^^^^^^^^^^^^^^^^^^^^^^^^^^^^^^
  File "/home/airflow/.local/lib/python3.12/site-packages/airflow/models/baseoperator.py", line 401, in wrapper
    return func(self, *args, **kwargs)
           ^^^^^^^^^^^^^^^^^^^^^^^^^^^
  File "/home/airflow/.local/lib/python3.12/site-packages/mlflow_provider/operators/pyfunc.py", line 165, in execute
    requirements_file_name = pyfunc.get_model_dependencies(self.model_uri)
                             ^^^^^^^^^^^^^^^^^^^^^^^^^^^^^^^^^^^^^^^^^^^^^
  File "/home/airflow/.local/lib/python3.12/site-packages/mlflow/pyfunc/__init__.py", line 1235, in get_model_dependencies
    dep_file = _get_model_dependencies(model_uri, format)
               ^^^^^^^^^^^^^^^^^^^^^^^^^^^^^^^^^^^^^^^^^^
  File "/home/airflow/.local/lib/python3.12/site-packages/mlflow/pyfunc/__init__.py", line 1155, in _get_model_dependencies
    model_dir = _download_artifact_from_uri(model_uri)
                ^^^^^^^^^^^^^^^^^^^^^^^^^^^^^^^^^^^^^^
  File "/home/airflow/.local/lib/python3.12/site-packages/mlflow/tracking/artifact_utils.py", line 108, in _download_artifact_from_uri
    repo = get_artifact_repository(artifact_uri=root_uri)
           ^^^^^^^^^^^^^^^^^^^^^^^^^^^^^^^^^^^^^^^^^^^^^^
  File "/home/airflow/.local/lib/python3.12/site-packages/mlflow/store/artifact/artifact_repository_registry.py", line 124, in get_artifact_repository
    return _artifact_repository_registry.get_artifact_repository(artifact_uri)
           ^^^^^^^^^^^^^^^^^^^^^^^^^^^^^^^^^^^^^^^^^^^^^^^^^^^^^^^^^^^^^^^^^^^
  File "/home/airflow/.local/lib/python3.12/site-packages/mlflow/store/artifact/artifact_repository_registry.py", line 77, in get_artifact_repository
    return repository(artifact_uri)
           ^^^^^^^^^^^^^^^^^^^^^^^^
  File "/home/airflow/.local/lib/python3.12/site-packages/mlflow/store/artifact/mlflow_artifacts_repo.py", line 45, in __init__
    super().__init__(self.resolve_uri(artifact_uri, get_tracking_uri()))
                     ^^^^^^^^^^^^^^^^^^^^^^^^^^^^^^^^^^^^^^^^^^^^^^^^^^
  File "/home/airflow/.local/lib/python3.12/site-packages/mlflow/store/artifact/mlflow_artifacts_repo.py", line 59, in resolve_uri
    _validate_uri_scheme(track_parse.scheme)
  File "/home/airflow/.local/lib/python3.12/site-packages/mlflow/store/artifact/mlflow_artifacts_repo.py", line 35, in _validate_uri_scheme
    raise MlflowException(
mlflow.exceptions.MlflowException: The configured tracking uri scheme: '' is invalid for use with the proxy mlflow-artifact scheme. The allowed tracking schemes are: {'http', 'https'}
[2024-07-16T14:14:11.482+0000] {taskinstance.py:1206} INFO - Marking task as FAILED. dag_id=dag_with_postgres_hooks, task_id=predict_mlflow, run_id=manual__2024-07-16T14:14:03.434794+00:00, execution_date=20240716T141403, start_date=20240716T141411, end_date=20240716T141411
[2024-07-16T14:14:11.487+0000] {standard_task_runner.py:110} ERROR - Failed to execute job 30 for task predict_mlflow (The configured tracking uri scheme: '' is invalid for use with the proxy mlflow-artifact scheme. The allowed tracking schemes are: {'http', 'https'}; 632)
[2024-07-16T14:14:11.495+0000] {local_task_job_runner.py:240} INFO - Task exited with return code 1
[2024-07-16T14:14:11.501+0000] {taskinstance.py:3503} INFO - 0 downstream tasks scheduled from follow-on schedule check
[2024-07-16T14:14:11.501+0000] {local_task_job_runner.py:222} INFO - ::endgroup::
