[2024-07-22T08:50:53.342+0000] {local_task_job_runner.py:120} INFO - ::group::Pre task execution logs
[2024-07-22T08:50:53.352+0000] {taskinstance.py:2076} INFO - Dependencies all met for dep_context=non-requeueable deps ti=<TaskInstance: dag_with_postgres_hooks.pred_time_series manual__2024-07-22T08:50:35.399751+00:00 [queued]>
[2024-07-22T08:50:53.355+0000] {taskinstance.py:2076} INFO - Dependencies all met for dep_context=requeueable deps ti=<TaskInstance: dag_with_postgres_hooks.pred_time_series manual__2024-07-22T08:50:35.399751+00:00 [queued]>
[2024-07-22T08:50:53.356+0000] {taskinstance.py:2306} INFO - Starting attempt 1 of 1
[2024-07-22T08:50:53.361+0000] {taskinstance.py:2330} INFO - Executing <Task(PythonOperator): pred_time_series> on 2024-07-22 08:50:35.399751+00:00
[2024-07-22T08:50:53.366+0000] {warnings.py:112} WARNING - /home/***/.local/lib/python3.12/site-packages/***/task/task_runner/standard_task_runner.py:62: DeprecationWarning: This process (pid=4378) is multi-threaded, use of fork() may lead to deadlocks in the child.
  pid = os.fork()

[2024-07-22T08:50:53.368+0000] {standard_task_runner.py:90} INFO - Running: ['***', 'tasks', 'run', 'dag_with_postgres_hooks', 'pred_time_series', 'manual__2024-07-22T08:50:35.399751+00:00', '--job-id', '507', '--raw', '--subdir', 'DAGS_FOLDER/Stock_pred.py', '--cfg-path', '/tmp/tmpj5g5px9_']
[2024-07-22T08:50:53.369+0000] {standard_task_runner.py:64} INFO - Started process 4389 to run task
[2024-07-22T08:50:53.369+0000] {standard_task_runner.py:91} INFO - Job 507: Subtask pred_time_series
[2024-07-22T08:50:53.386+0000] {task_command.py:426} INFO - Running <TaskInstance: dag_with_postgres_hooks.pred_time_series manual__2024-07-22T08:50:35.399751+00:00 [running]> on host d89911194c67
[2024-07-22T08:50:53.414+0000] {taskinstance.py:2648} INFO - Exporting env vars: AIRFLOW_CTX_DAG_EMAIL='***@example.com' AIRFLOW_CTX_DAG_OWNER='***' AIRFLOW_CTX_DAG_ID='dag_with_postgres_hooks' AIRFLOW_CTX_TASK_ID='pred_time_series' AIRFLOW_CTX_EXECUTION_DATE='2024-07-22T08:50:35.399751+00:00' AIRFLOW_CTX_TRY_NUMBER='1' AIRFLOW_CTX_DAG_RUN_ID='manual__2024-07-22T08:50:35.399751+00:00'
[2024-07-22T08:50:53.415+0000] {taskinstance.py:430} INFO - ::endgroup::
[2024-07-22T08:50:53.491+0000] {warnings.py:112} WARNING - /opt/***/dags/Stock_pred.py:260: SettingWithCopyWarning: 
A value is trying to be set on a copy of a slice from a DataFrame

See the caveats in the documentation: https://pandas.pydata.org/pandas-docs/stable/user_guide/indexing.html#returning-a-view-versus-a-copy
  df_new_ts.rename(index={0:date},inplace=True)

[2024-07-22T08:50:53.491+0000] {taskinstance.py:441} INFO - ::group::Post task execution logs
[2024-07-22T08:50:53.491+0000] {taskinstance.py:2905} ERROR - Task failed with exception
Traceback (most recent call last):
  File "/home/airflow/.local/lib/python3.12/site-packages/airflow/models/taskinstance.py", line 465, in _execute_task
    result = _execute_callable(context=context, **execute_callable_kwargs)
             ^^^^^^^^^^^^^^^^^^^^^^^^^^^^^^^^^^^^^^^^^^^^^^^^^^^^^^^^^^^^^
  File "/home/airflow/.local/lib/python3.12/site-packages/airflow/models/taskinstance.py", line 432, in _execute_callable
    return execute_callable(context=context, **execute_callable_kwargs)
           ^^^^^^^^^^^^^^^^^^^^^^^^^^^^^^^^^^^^^^^^^^^^^^^^^^^^^^^^^^^^
  File "/home/airflow/.local/lib/python3.12/site-packages/airflow/models/baseoperator.py", line 401, in wrapper
    return func(self, *args, **kwargs)
           ^^^^^^^^^^^^^^^^^^^^^^^^^^^
  File "/home/airflow/.local/lib/python3.12/site-packages/airflow/operators/python.py", line 235, in execute
    return_value = self.execute_callable()
                   ^^^^^^^^^^^^^^^^^^^^^^^
  File "/home/airflow/.local/lib/python3.12/site-packages/airflow/operators/python.py", line 252, in execute_callable
    return self.python_callable(*self.op_args, **self.op_kwargs)
           ^^^^^^^^^^^^^^^^^^^^^^^^^^^^^^^^^^^^^^^^^^^^^^^^^^^^^
  File "/opt/airflow/dags/Stock_pred.py", line 262, in pred_time_series
    df_old_ts.set_index("DATE",inplace=True)
  File "/home/airflow/.local/lib/python3.12/site-packages/pandas/core/frame.py", line 5870, in set_index
    raise KeyError(f"None of {missing} are in the columns")
KeyError: "None of ['DATE'] are in the columns"
[2024-07-22T08:50:53.496+0000] {taskinstance.py:1206} INFO - Marking task as FAILED. dag_id=dag_with_postgres_hooks, task_id=pred_time_series, run_id=manual__2024-07-22T08:50:35.399751+00:00, execution_date=20240722T085035, start_date=20240722T085053, end_date=20240722T085053
[2024-07-22T08:50:53.501+0000] {standard_task_runner.py:110} ERROR - Failed to execute job 507 for task pred_time_series ("None of ['DATE'] are in the columns"; 4389)
[2024-07-22T08:50:53.511+0000] {local_task_job_runner.py:243} INFO - Task exited with return code 1
[2024-07-22T08:50:53.521+0000] {taskinstance.py:3503} INFO - 0 downstream tasks scheduled from follow-on schedule check
[2024-07-22T08:50:53.523+0000] {local_task_job_runner.py:222} INFO - ::endgroup::
