[2025-03-26T20:21:47.937+0000] {local_task_job_runner.py:120} INFO - ::group::Pre task execution logs
[2025-03-26T20:21:47.965+0000] {taskinstance.py:2076} INFO - Dependencies all met for dep_context=non-requeueable deps ti=<TaskInstance: dag_with_postgres_hooks.plot scheduled__2025-03-24T13:30:00+00:00 [queued]>
[2025-03-26T20:21:47.972+0000] {taskinstance.py:2076} INFO - Dependencies all met for dep_context=requeueable deps ti=<TaskInstance: dag_with_postgres_hooks.plot scheduled__2025-03-24T13:30:00+00:00 [queued]>
[2025-03-26T20:21:47.972+0000] {taskinstance.py:2306} INFO - Starting attempt 1 of 1
[2025-03-26T20:21:48.016+0000] {taskinstance.py:2330} INFO - Executing <Task(PythonOperator): plot> on 2025-03-24 13:30:00+00:00
[2025-03-26T20:21:48.033+0000] {warnings.py:112} WARNING - /home/***/.local/lib/python3.12/site-packages/***/task/task_runner/standard_task_runner.py:62: DeprecationWarning: This process (pid=485) is multi-threaded, use of fork() may lead to deadlocks in the child.
  pid = os.fork()

[2025-03-26T20:21:48.040+0000] {standard_task_runner.py:64} INFO - Started process 540 to run task
[2025-03-26T20:21:48.040+0000] {standard_task_runner.py:90} INFO - Running: ['***', 'tasks', 'run', 'dag_with_postgres_hooks', 'plot', 'scheduled__2025-03-24T13:30:00+00:00', '--job-id', '1777', '--raw', '--subdir', 'DAGS_FOLDER/Stock_pred.py', '--cfg-path', '/tmp/tmpezpe7y0z']
[2025-03-26T20:21:48.044+0000] {standard_task_runner.py:91} INFO - Job 1777: Subtask plot
[2025-03-26T20:21:48.077+0000] {task_command.py:426} INFO - Running <TaskInstance: dag_with_postgres_hooks.plot scheduled__2025-03-24T13:30:00+00:00 [running]> on host b7aba691e1ff
[2025-03-26T20:21:48.196+0000] {taskinstance.py:2648} INFO - Exporting env vars: AIRFLOW_CTX_DAG_EMAIL='***@example.com' AIRFLOW_CTX_DAG_OWNER='***' AIRFLOW_CTX_DAG_ID='dag_with_postgres_hooks' AIRFLOW_CTX_TASK_ID='plot' AIRFLOW_CTX_EXECUTION_DATE='2025-03-24T13:30:00+00:00' AIRFLOW_CTX_TRY_NUMBER='1' AIRFLOW_CTX_DAG_RUN_ID='scheduled__2025-03-24T13:30:00+00:00'
[2025-03-26T20:21:48.199+0000] {taskinstance.py:430} INFO - ::endgroup::
[2025-03-26T20:21:48.292+0000] {logging_mixin.py:188} INFO -            DATE    CLOSE
0    2022-12-30  15366.0
1    2023-01-03  15927.0
2    2023-01-04  15892.0
3    2023-01-05  16033.0
4    2023-01-06  16243.0
..          ...      ...
185  2025-03-18  26300.0
186  2025-03-19  26200.0
187  2025-03-20  26250.0
188  2025-03-21  26100.0
189  2025-03-26  26150.0

[190 rows x 2 columns]
[2025-03-26T20:21:48.306+0000] {logging_mixin.py:188} INFO - 2025-03-26
[2025-03-26T20:21:48.313+0000] {logging_mixin.py:188} INFO - 2025-03-27 00:00:00
[2025-03-26T20:21:48.319+0000] {logging_mixin.py:188} INFO -                      pred_index
2025-03-26              26150.0
2025-03-27 00:00:00     26061.0
[2025-03-26T20:21:48.327+0000] {logging_mixin.py:188} INFO -             pred_index
2025-03-26     26150.0
2025-03-27     26061.0
[2025-03-26T20:21:48.336+0000] {logging_mixin.py:188} INFO -        CLOSE        DATE
0    15366.0  2022-12-30
1    15927.0  2023-01-03
2    15892.0  2023-01-04
3    16033.0  2023-01-05
4    16243.0  2023-01-06
..       ...         ...
185  26300.0  2025-03-18
186  26200.0  2025-03-19
187  26250.0  2025-03-20
188  26100.0  2025-03-21
189  26150.0  2025-03-26

[190 rows x 2 columns]
[2025-03-26T20:21:48.344+0000] {logging_mixin.py:188} INFO -    pred_index        date
0     26150.0  2025-03-26
1     26061.0  2025-03-27
[2025-03-26T20:26:57.748+0000] {taskinstance.py:441} INFO - ::group::Post task execution logs
[2025-03-26T20:26:57.751+0000] {taskinstance.py:2905} ERROR - Task failed with exception
Traceback (most recent call last):
  File "/home/airflow/.local/lib/python3.12/site-packages/urllib3/connectionpool.py", line 537, in _make_request
    response = conn.getresponse()
               ^^^^^^^^^^^^^^^^^^
  File "/home/airflow/.local/lib/python3.12/site-packages/urllib3/connection.py", line 461, in getresponse
    httplib_response = super().getresponse()
                       ^^^^^^^^^^^^^^^^^^^^^
  File "/usr/local/lib/python3.12/http/client.py", line 1428, in getresponse
    response.begin()
  File "/usr/local/lib/python3.12/http/client.py", line 331, in begin
    version, status, reason = self._read_status()
                              ^^^^^^^^^^^^^^^^^^^
  File "/usr/local/lib/python3.12/http/client.py", line 292, in _read_status
    line = str(self.fp.readline(_MAXLINE + 1), "iso-8859-1")
               ^^^^^^^^^^^^^^^^^^^^^^^^^^^^^^
  File "/usr/local/lib/python3.12/socket.py", line 708, in readinto
    return self._sock.recv_into(b)
           ^^^^^^^^^^^^^^^^^^^^^^^
TimeoutError: timed out

The above exception was the direct cause of the following exception:

Traceback (most recent call last):
  File "/home/airflow/.local/lib/python3.12/site-packages/botocore/httpsession.py", line 464, in send
    urllib_response = conn.urlopen(
                      ^^^^^^^^^^^^^
  File "/home/airflow/.local/lib/python3.12/site-packages/urllib3/connectionpool.py", line 845, in urlopen
    retries = retries.increment(
              ^^^^^^^^^^^^^^^^^^
  File "/home/airflow/.local/lib/python3.12/site-packages/urllib3/util/retry.py", line 445, in increment
    raise reraise(type(error), error, _stacktrace)
          ^^^^^^^^^^^^^^^^^^^^^^^^^^^^^^^^^^^^^^^^
  File "/home/airflow/.local/lib/python3.12/site-packages/urllib3/util/util.py", line 39, in reraise
    raise value
  File "/home/airflow/.local/lib/python3.12/site-packages/urllib3/connectionpool.py", line 791, in urlopen
    response = self._make_request(
               ^^^^^^^^^^^^^^^^^^^
  File "/home/airflow/.local/lib/python3.12/site-packages/urllib3/connectionpool.py", line 539, in _make_request
    self._raise_timeout(err=e, url=url, timeout_value=read_timeout)
  File "/home/airflow/.local/lib/python3.12/site-packages/urllib3/connectionpool.py", line 371, in _raise_timeout
    raise ReadTimeoutError(
urllib3.exceptions.ReadTimeoutError: AWSHTTPConnectionPool(host='host.docker.internal', port=9005): Read timed out. (read timeout=60)

During handling of the above exception, another exception occurred:

Traceback (most recent call last):
  File "/home/airflow/.local/lib/python3.12/site-packages/airflow/models/taskinstance.py", line 465, in _execute_task
    result = _execute_callable(context=context, **execute_callable_kwargs)
             ^^^^^^^^^^^^^^^^^^^^^^^^^^^^^^^^^^^^^^^^^^^^^^^^^^^^^^^^^^^^^
  File "/home/airflow/.local/lib/python3.12/site-packages/airflow/models/taskinstance.py", line 432, in _execute_callable
    return execute_callable(context=context, **execute_callable_kwargs)
           ^^^^^^^^^^^^^^^^^^^^^^^^^^^^^^^^^^^^^^^^^^^^^^^^^^^^^^^^^^^^
  File "/home/airflow/.local/lib/python3.12/site-packages/airflow/models/baseoperator.py", line 401, in wrapper
    return func(self, *args, **kwargs)
           ^^^^^^^^^^^^^^^^^^^^^^^^^^^
  File "/home/airflow/.local/lib/python3.12/site-packages/airflow/operators/python.py", line 235, in execute
    return_value = self.execute_callable()
                   ^^^^^^^^^^^^^^^^^^^^^^^
  File "/home/airflow/.local/lib/python3.12/site-packages/airflow/operators/python.py", line 252, in execute_callable
    return self.python_callable(*self.op_args, **self.op_kwargs)
           ^^^^^^^^^^^^^^^^^^^^^^^^^^^^^^^^^^^^^^^^^^^^^^^^^^^^^
  File "/opt/airflow/dags/Stock_pred.py", line 366, in plot
    s3.meta.client.upload_file(temp_model_location, 'mlflow-artifacts', 'plot.jpg')
  File "/home/airflow/.local/lib/python3.12/site-packages/boto3/s3/inject.py", line 145, in upload_file
    return transfer.upload_file(
           ^^^^^^^^^^^^^^^^^^^^^
  File "/home/airflow/.local/lib/python3.12/site-packages/boto3/s3/transfer.py", line 372, in upload_file
    future.result()
  File "/home/airflow/.local/lib/python3.12/site-packages/s3transfer/futures.py", line 103, in result
    return self._coordinator.result()
           ^^^^^^^^^^^^^^^^^^^^^^^^^^
  File "/home/airflow/.local/lib/python3.12/site-packages/s3transfer/futures.py", line 266, in result
    raise self._exception
  File "/home/airflow/.local/lib/python3.12/site-packages/s3transfer/tasks.py", line 139, in __call__
    return self._execute_main(kwargs)
           ^^^^^^^^^^^^^^^^^^^^^^^^^^
  File "/home/airflow/.local/lib/python3.12/site-packages/s3transfer/tasks.py", line 162, in _execute_main
    return_value = self._main(**kwargs)
                   ^^^^^^^^^^^^^^^^^^^^
  File "/home/airflow/.local/lib/python3.12/site-packages/s3transfer/upload.py", line 764, in _main
    client.put_object(Bucket=bucket, Key=key, Body=body, **extra_args)
  File "/home/airflow/.local/lib/python3.12/site-packages/botocore/client.py", line 565, in _api_call
    return self._make_api_call(operation_name, kwargs)
           ^^^^^^^^^^^^^^^^^^^^^^^^^^^^^^^^^^^^^^^^^^^
  File "/home/airflow/.local/lib/python3.12/site-packages/botocore/client.py", line 1001, in _make_api_call
    http, parsed_response = self._make_request(
                            ^^^^^^^^^^^^^^^^^^^
  File "/home/airflow/.local/lib/python3.12/site-packages/botocore/client.py", line 1027, in _make_request
    return self._endpoint.make_request(operation_model, request_dict)
           ^^^^^^^^^^^^^^^^^^^^^^^^^^^^^^^^^^^^^^^^^^^^^^^^^^^^^^^^^^
  File "/home/airflow/.local/lib/python3.12/site-packages/botocore/endpoint.py", line 119, in make_request
    return self._send_request(request_dict, operation_model)
           ^^^^^^^^^^^^^^^^^^^^^^^^^^^^^^^^^^^^^^^^^^^^^^^^^
  File "/home/airflow/.local/lib/python3.12/site-packages/botocore/endpoint.py", line 202, in _send_request
    while self._needs_retry(
          ^^^^^^^^^^^^^^^^^^
  File "/home/airflow/.local/lib/python3.12/site-packages/botocore/endpoint.py", line 354, in _needs_retry
    responses = self._event_emitter.emit(
                ^^^^^^^^^^^^^^^^^^^^^^^^^
  File "/home/airflow/.local/lib/python3.12/site-packages/botocore/hooks.py", line 412, in emit
    return self._emitter.emit(aliased_event_name, **kwargs)
           ^^^^^^^^^^^^^^^^^^^^^^^^^^^^^^^^^^^^^^^^^^^^^^^^
  File "/home/airflow/.local/lib/python3.12/site-packages/botocore/hooks.py", line 256, in emit
    return self._emit(event_name, kwargs)
           ^^^^^^^^^^^^^^^^^^^^^^^^^^^^^^
  File "/home/airflow/.local/lib/python3.12/site-packages/botocore/hooks.py", line 239, in _emit
    response = handler(**kwargs)
               ^^^^^^^^^^^^^^^^^
  File "/home/airflow/.local/lib/python3.12/site-packages/botocore/retryhandler.py", line 207, in __call__
    if self._checker(**checker_kwargs):
       ^^^^^^^^^^^^^^^^^^^^^^^^^^^^^^^
  File "/home/airflow/.local/lib/python3.12/site-packages/botocore/retryhandler.py", line 284, in __call__
    should_retry = self._should_retry(
                   ^^^^^^^^^^^^^^^^^^^
  File "/home/airflow/.local/lib/python3.12/site-packages/botocore/retryhandler.py", line 320, in _should_retry
    return self._checker(attempt_number, response, caught_exception)
           ^^^^^^^^^^^^^^^^^^^^^^^^^^^^^^^^^^^^^^^^^^^^^^^^^^^^^^^^^
  File "/home/airflow/.local/lib/python3.12/site-packages/botocore/retryhandler.py", line 363, in __call__
    checker_response = checker(
                       ^^^^^^^^
  File "/home/airflow/.local/lib/python3.12/site-packages/botocore/retryhandler.py", line 247, in __call__
    return self._check_caught_exception(
           ^^^^^^^^^^^^^^^^^^^^^^^^^^^^^
  File "/home/airflow/.local/lib/python3.12/site-packages/botocore/retryhandler.py", line 416, in _check_caught_exception
    raise caught_exception
  File "/home/airflow/.local/lib/python3.12/site-packages/botocore/endpoint.py", line 281, in _do_get_response
    http_response = self._send(request)
                    ^^^^^^^^^^^^^^^^^^^
  File "/home/airflow/.local/lib/python3.12/site-packages/botocore/endpoint.py", line 377, in _send
    return self.http_session.send(request)
           ^^^^^^^^^^^^^^^^^^^^^^^^^^^^^^^
  File "/home/airflow/.local/lib/python3.12/site-packages/botocore/httpsession.py", line 501, in send
    raise ReadTimeoutError(endpoint_url=request.url, error=e)
botocore.exceptions.ReadTimeoutError: Read timeout on endpoint URL: "http://host.docker.internal:9005/mlflow-artifacts/plot.jpg"
[2025-03-26T20:26:57.767+0000] {taskinstance.py:1206} INFO - Marking task as FAILED. dag_id=dag_with_postgres_hooks, task_id=plot, run_id=scheduled__2025-03-24T13:30:00+00:00, execution_date=20250324T133000, start_date=20250326T202147, end_date=20250326T202657
[2025-03-26T20:26:57.777+0000] {standard_task_runner.py:110} ERROR - Failed to execute job 1777 for task plot (Read timeout on endpoint URL: "http://host.docker.internal:9005/mlflow-artifacts/plot.jpg"; 540)
[2025-03-26T20:26:57.824+0000] {local_task_job_runner.py:243} INFO - Task exited with return code 1
[2025-03-26T20:26:57.840+0000] {taskinstance.py:3503} INFO - 0 downstream tasks scheduled from follow-on schedule check
[2025-03-26T20:26:57.842+0000] {local_task_job_runner.py:222} INFO - ::endgroup::
